set SUDO_PW
Already running somewhere
Traceback (most recent call last):
  File "/usr/lib/python3/dist-packages/pexpect/spawnbase.py", line 144, in read_nonblocking
    s = os.read(self.child_fd, size)
OSError: [Errno 5] Input/output error

During handling of the above exception, another exception occurred:

Traceback (most recent call last):
  File "/usr/lib/python3/dist-packages/pexpect/expect.py", line 97, in expect_loop
    incoming = spawn.read_nonblocking(spawn.maxread, timeout)
  File "/usr/lib/python3/dist-packages/pexpect/pty_spawn.py", line 455, in read_nonblocking
    return super(spawn, self).read_nonblocking(size)
  File "/usr/lib/python3/dist-packages/pexpect/spawnbase.py", line 149, in read_nonblocking
    raise EOF('End Of File (EOF). Exception style platform.')
pexpect.exceptions.EOF: End Of File (EOF). Exception style platform.

During handling of the above exception, another exception occurred:

Traceback (most recent call last):
  File "./vpn_sign_in.py", line 42, in <module>
    
  File "/usr/lib/python3/dist-packages/pexpect/spawnbase.py", line 384, in expect_exact
    return exp.expect_loop(timeout)
  File "/usr/lib/python3/dist-packages/pexpect/expect.py", line 102, in expect_loop
    return self.eof(e)
  File "/usr/lib/python3/dist-packages/pexpect/expect.py", line 49, in eof
    raise EOF(msg)
pexpect.exceptions.EOF: End Of File (EOF). Exception style platform.
<pexpect.pty_spawn.spawn object at 0x7fb15a8f4ba8>
command: /usr/bin/sudo
args: ['/usr/bin/sudo', 'vpnc-connect', 'ghs']
searcher: None
buffer (last 100 chars): b''
before (last 100 chars): b"\r\nvpnc-connect: unknown host `vpn-gw.ghs.com'\r\n\r\n"
after: <class 'pexpect.exceptions.EOF'>
match: None
match_index: None
exitstatus: 1
flag_eof: True
pid: 22359
child_fd: 6
closed: False
timeout: 30
delimiter: <class 'pexpect.exceptions.EOF'>
logfile: None
logfile_read: None
logfile_send: None
maxread: 2000
ignorecase: False
searchwindowsize: None
delaybeforesend: 0.05
delayafterclose: 0.1
delayafterterminate: 0.1
